I'm sorry, but an uncaught exception occurred.

While parsing C:\Users\Pandora\Desktop\RPY Projects\Our-current-project\game/chapter-0.rpy.
Exception: Line with id Test_c6daba82 appeared twice, at game/chapter-0.rpy:5 and game/doki.rpy:5.

-- Full Traceback ------------------------------------------------------------

Full traceback:
  File "renpy/bootstrap.py", line 277, in bootstrap
    renpy.main.main()
  File "renpy/main.py", line 490, in main
    renpy.game.script.load_script() # sets renpy.game.script.
  File "renpy/script.py", line 297, in load_script
    self.load_appropriate_file(".rpyc", ".rpy", dir, fn, initcode)
  File "renpy/script.py", line 809, in load_appropriate_file
    self.finish_load(stmts, initcode, filename=lastfn) # type: ignore
  File "renpy/script.py", line 427, in finish_load
    self.translator.take_translates(all_stmts)
  File "renpy/translation/__init__.py", line 169, in take_translates
    n.filename, n.linenumber))
Exception: Line with id Test_c6daba82 appeared twice, at game/chapter-0.rpy:5 and game/doki.rpy:5.

Windows-10-10.0.22621 AMD64
Ren'Py 7.5.3.22090809
 
Mon Apr 17 18:14:47 2023
